Workbook
Name Slicer_Gender: #N/A
Name Slicer_Parental_Education_Level: #N/A

Sheet Sheet1
A3: Row Labels | B3: Average of Final_Exam_Score | D3: Row Labels | E3: Average of Final_Exam_Score | G3: Row Labels | H3: Count of Student_ID
A4: Female | B4: 51.013973 | D4: 0-4 | E4: 47.499105 | G4: Female | H4: 314
A5: Male | B5: 51.119108 | D5: 5-9 | E5: 47.963473 | G5: Male | H5: 286
A6: Grand Total | B6: 51.064087 | D6: 10-14 | E6: 49.603424 | G6: Grand Total | H6: 600
D7: 15-19 | E7: 52.043548
D8: 20-24 | E8: 52.910909
A9: Row Labels | B9: Average of Final_Exam_Score | D9: 25-30 | E9: 54.414444
A10: Bachelor | B10: 51.200102 | D10: Grand Total | E10: 51.064087
A11: Diploma | B11: 51.33268
A12: High School | B12: 51.558908 | D12: Row Labels | E12: Average of Final_Exam_Score
A13: Master | B13: 50.523273 | D13: 65-75 | E13: 48.438217
A14: PhD | B14: 50.62544 | D14: 75-85 | E14: 50.939434
A15: Grand Total | B15: 51.064087 | D15: 85-95 | E15: 52.126148
D16: 95-105 | E16: 54.785823
D17: Grand Total | E17: 51.064087

Sheet Student_Performance_Statistical
A1: Student_ID | B1: Gender | C1: Age | D1: Study_Hours_Per_Week | E1: Attendance_Rate | F1: Parental_Education_Level | G1: Family_Income_Level | H1: Internet_Access | I1: Previous_Grade | J1: Sleep_Hours_Per_Night | K1: Final_Exam_Score | L1: Extracurricular_Participation | M1: Pass/Fail
A2: STD-2000 | B2: Male | C2: 16 | D2: 13 | E2: 98.4 | F2: Diploma | G2: Low | H2: Yes | I2: 47 | J2: 4.2 | K2: 43.808719 | L2: Yes | M2: =IF(Table2[[#This Row],[Final_Exam_Score]]>= 50,"Pass","Fail") -> Fail
A3: STD-2001 | B3: Female | C3: 16 | D3: 6 | E3: 68.04 | F3: High School | G3: Low | H3: Yes | I3: 97 | J3: 6.4 | K3: 55.874397 | L3: Yes | M3: =IF(Table2[[#This Row],[Final_Exam_Score]]>= 50,"Pass","Fail") -> Pass
A4: STD-2002 | B4: Male | C4: 20 | D4: 9 | E4: 81.22 | F4: Diploma | G4: Low | H4: Yes | I4: 70 | J4: 8.4 | K4: 49.603034 | L4: Yes | M4: =IF(Table2[[#This Row],[Final_Exam_Score]]>= 50,"Pass","Fail") -> Fail
A5: STD-2003 | B5: Male | C5: 15 | D5: 20 | E5: 67.04 | F5: Master | G5: Middle | H5: Yes | I5: 45 | J5: 8.1 | K5: 40 | L5: No | M5: =IF(Table2[[#This Row],[Final_Exam_Score]]>= 50,"Pass","Fail") -> Fail
A6: STD-2004 | B6: Male | C6: 15 | D6: 14 | E6: 83.85 | F6: Diploma | G6: High | H6: No | I6: 59 | J6: 7.6 | K6: 40 | L6: Yes | M6: =IF(Table2[[#This Row],[Final_Exam_Score]]>= 50,"Pass","Fail") -> Fail
A7: STD-2005 | B7: Male | C7: 17 | D7: 29 | E7: 70.11 | F7: Bachelor | G7: High | H7: No | I7: 48 | J7: 8.3 | K7: 41.703035 | L7: No | M7: =IF(Table2[[#This Row],[Final_Exam_Score]]>= 50,"Pass","Fail") -> Fail
A8: STD-2006 | B8: Male | C8: 18 | D8: 7 | E8: 87.19 | F8: Bachelor | G8: High | H8: No | I8: 56 | J8: 7.7 | K8: 44.503041 | L8: Yes | M8: =IF(Table2[[#This Row],[Final_Exam_Score]]>= 50,"Pass","Fail") -> Fail
A9: STD-2007 | B9: Female | C9: 17 | D9: 6 | E9: 74.25 | F9: Master | G9: Middle | H9: No | I9: 66 | J9: 4.1 | K9: 45.607991 | L9: No | M9: =IF(Table2[[#This Row],[Final_Exam_Score]]>= 50,"Pass","Fail") -> Fail
A10: STD-2008 | B10: Female | C10: 16 | D10: 8 | E10: 89.18 | F10: PhD | G10: High | H10: No | I10: 68 | J10: 6.4 | K10: 56.086276 | L10: No | M10: =IF(Table2[[#This Row],[Final_Exam_Score]]>= 50,"Pass","Fail") -> Pass
A11: STD-2009 | B11: Male | C11: 18 | D11: 5 | E11: 77.15 | F11: Bachelor | G11: High | H11: Yes | I11: 77 | J11: 4.1 | K11: 45.23348 | L11: No | M11: =IF(Table2[[#This Row],[Final_Exam_Score]]>= 50,"Pass","Fail") -> Fail
A12: STD-2010 | B12: Female | C12: 17 | D12: 18 | E12: 65.15 | F12: Diploma | G12: Low | H12: No | I12: 61 | J12: 6.8 | K12: 40 | L12: Yes | M12: =IF(Table2[[#This Row],[Final_Exam_Score]]>= 50,"Pass","Fail") -> Fail
A13: STD-2011 | B13: Female | C13: 17 | D13: 6 | E13: 75.32 | F13: Master | G13: Middle | H13: Yes | I13: 67 | J13: 5.2 | K13: 40.939857 | L13: Yes | M13: =IF(Table2[[#This Row],[Final_Exam_Score]]>= 50,"Pass","Fail") -> Fail
... A601: STD-2599 | B601: Female | C601: 21 | D601: 5 | E601: 89.27 | F601: PhD | G601: High | H601: Yes | I601: 49 | J601: 8.4 | K601: 40 | L601: Yes | M601: =IF(Table2[[#This Row],[Final_Exam_Score]]>= 50,"Pass","Fail") -> Fail

Sheet T- test
A1: t-Test: Two-Sample Assuming Equal Variances
B3: Variable 1 | C3: Variable 2
A4: Mean | B4: 51.119108 | C4: 51.013973
A5: Variance | B5: 68.188398 | C5: 66.966512
A6: Observations | B6: 286 | C6: 314
A7: Pooled Variance | B7: 67.548849
A8: Hypothesized Mean Difference | B8: 0
A9: df | B9: 598
A10: t Stat | B10: 0.1564979
A11: P(T<=t) one-tail | B11: 0.4378467
A12: t Critical one-tail | B12: 1.6474057
A13: P(T<=t) two-tail | B13: 0.87569339
A14: t Critical two-tail | B14: 1.9639389

Sheet ANOVA
A1: Anova: Single Factor
A3: SUMMARY
A4: Groups | B4: Count | C4: Sum | D4: Average | E4: Variance
A5: 55.874397 | B5: 74 | C5: 3865.7368 | D5: 52.239687 | E5: 66.451765
A6: 40 | B6: 58 | C6: 2922.9981 | D6: 50.396518 | E6: 62.035278
A7: 44.941215 | B7: 68 | C7: 3489.435 | D7: 51.31522 | E7: 71.911003
A8: 45.607991 | B8: 52 | C8: 2652.0477 | D8: 51.000917 | E8: 66.989802
A9: 56.086276 | B9: 56 | C9: 2805.6601 | D9: 50.101074 | E9: 68.996429
A12: ANOVA
A13: Source of Variation | B13: SS | C13: df | D13: MS | E13: F | F13: P-value | G13: F crit
A14: Between Groups | B14: 184.33333 | C14: 4 | D14: 46.083332 | E14: 0.68392619 | F14: 0.60355786 | G14: 2.4014425
A15: Within Groups | B15: 20416.31 | C15: 303 | D15: 67.380563
A17: Total | B17: 20600.644 | C17: 307

Sheet Regression analysis
A1: SUMMARY OUTPUT
A3: Regression Statistics
A4: Multiple R | B4: 0.83883577
A5: R Square | B5: 0.70364544
A6: Adjusted R Square | B6: 0.70165314
A7: Standard Error | B7: 4.4855509
A8: Observations | B8: 600
A10: ANOVA
B11: df | C11: SS | D11: MS | E11: F | F11: Significance F
A12: Regression | B12: 4 | C12: 28424.367 | D12: 7106.0918 | E12: 353.18255 | F12: 1.5376774e-155
A13: Residual | B13: 595 | C13: 11971.499 | D13: 20.120167
A14: Total | B14: 599 | C14: 40395.866
B16: Coefficients | C16: Standard Error | D16: t Stat | E16: P-value | F16: Lower 95% | G16: Upper 95% | H16: Lower 95.0% | I16: Upper 95.0%
A17: Intercept | B17: 2.8632413 | C17: 1.8517232 | D17: 1.5462577 | E17: 0.12257403 | F17: -0.77346715 | G17: 6.4999498 | H17: -0.77346715 | I17: 6.4999498
A18: Sleep hour | B18: -0.027670562 | C18: 0.13107736 | D18: -0.211101 | E18: 0.83288074 | F18: -0.28510112 | G18: 0.22976 | H18: -0.28510112 | I18: 0.22976
A19: Previous grade | B19: 0.37666886 | C19: 0.011475528 | D19: 32.823664 | E19: 1.2168264e-135 | F19: 0.35413139 | G19: 0.39920633 | H19: 0.35413139 | I19: 0.39920633
A20: Study hour | B20: 0.28099712 | C20: 0.022350564 | D20: 12.572261 | E20: 2.5852542e-32 | F20: 0.23710153 | G20: 0.32489271 | H20: 0.23710153 | I20: 0.32489271
A21: Attendance | B21: 0.19983347 | C21: 0.017267208 | D21: 11.573004 | E21: 4.4483926e-28 | F21: 0.16592138 | G21: 0.23374556 | H21: 0.16592138 | I21: 0.23374556

Sheet Sheet2
A1: Male score | B1: female score | P1: Final_Exam_Score | Q1: SLEEP | R1: PREVIOUS | S1: STUDY | T1: attend
A2: 43.808719 | B2: 55.874397 | P2: 43.808719 | Q2: 4.2 | R2: 47 | S2: 13 | T2: 98.4
A3: 49.603034 | B3: 45.607991 | P3: 55.874397 | Q3: 6.4 | R3: 97 | S3: 6 | T3: 68.04
A4: 40 | B4: 56.086276 | I4: high school | J4: diploma | K4: bachelor | L4: master | M4: phd | P4: 49.603034 | Q4: 8.4 | R4: 70 | S4: 9 | T4: 81.22
A5: 40 | B5: 40 | I5: 55.874397 | J5: 40 | K5: 44.941215 | L5: 45.607991 | M5: 56.086276 | P5: 40 | Q5: 8.1 | R5: 45 | S5: 20 | T5: 67.04
A6: 41.703035 | B6: 40.939857 | I6: 51.998142 | J6: 40.389974 | K6: 50.10782 | L6: 40.939857 | M6: 44.646718 | P6: 40 | Q6: 7.6 | R6: 59 | S6: 14 | T6: 83.85
A7: 44.503041 | B7: 44.941215 | I7: 51.660642 | J7: 54.789114 | K7: 42.033808 | L7: 58.395108 | M7: 53.340133 | P7: 41.703035 | Q7: 8.3 | R7: 48 | S7: 29 | T7: 70.11
A8: 45.23348 | B8: 51.998142 | I8: 47.11255 | J8: 48.169013 | K8: 52.766294 | L8: 57.622026 | M8: 48.779511 | P8: 44.503041 | Q8: 7.7 | R8: 56 | S8: 7 | T8: 87.19
A9: 43.161029 | B9: 51.660642 | I9: 42.997287 | J9: 67.071392 | K9: 43.534506 | L9: 53.291153 | M9: 60.105877 | P9: 45.607991 | Q9: 4.1 | R9: 66 | S9: 6 | T9: 74.25
A10: 40 | B10: 50.10782 | I10: 61.139746 | J10: 44.604625 | K10: 51.167231 | L10: 44.219741 | M10: 44.142066 | P10: 56.086276 | Q10: 6.4 | R10: 68 | S10: 8 | T10: 89.18
A11: 44.854443 | B11: 40.389974 | I11: 55.379274 | J11: 59.554344 | K11: 46.640868 | L11: 49.571326 | M11: 64.288148 | P11: 45.23348 | Q11: 4.1 | R11: 77 | S11: 5 | T11: 77.15
A12: 52.173816 | B12: 54.789114 | I12: 56.531947 | J12: 45.469367 | K12: 62.490229 | L12: 41.161005 | M12: 52.443307 | P12: 40 | Q12: 6.8 | R12: 61 | S12: 18 | T12: 65.15
A13: 46.163935 | B13: 42.033808 | I13: 73.158164 | J13: 44.767391 | K13: 47.000767 | L13: 40 | M13: 50.911657 | P13: 40.939857 | Q13: 5.2 | R13: 67 | S13: 6 | T13: 75.32
A14: 50.640692 | B14: 48.169013 | I14: 54.355617 | J14: 40 | K14: 61.818449 | L14: 55.58474 | M14: 54.370676 | P14: 43.161029 | Q14: 6.2 | R14: 71 | S14: 11 | T14: 67.87
A15: 67.550906 | B15: 52.766294 | I15: 49.437151 | J15: 61.235429 | K15: 40 | L15: 50.751464 | M15: 64.250143 | P15: 44.941215 | Q15: 5 | R15: 73 | S15: 11 | T15: 82.33
A16: 53.024154 | B16: 58.395108 | I16: 49.398098 | J16: 42.137007 | K16: 43.294812 | L16: 40 | M16: 40 | P16: 40 | Q16: 8.1 | R16: 59 | S16: 18 | T16: 75.11
... A57: 57.963952 | B57: 42.063154 | I57: 65.242855 | J57: 62.73773 | K57: 44.73609 | L57: 40 | M57: 47.246985 | P57: 40 | Q57: 5.1 | R57: 48 | S57: 14 | T57: 75.75
A58: 56.956722 | B58: 41.771779 | I58: 57.973957 | J58: 43.264153 | K58: 46.749215 | M58: 45.883709 | P58: 53.291153 | Q58: 5.6 | R58: 72 | S58: 18 | T58: 88.43
A59: 43.387219 | B59: 40 | I59: 43.331087 | J59: 50.637437 | K59: 51.091742 | M59: 40.910958 | P59: 55.232441 | Q59: 8.7 | R59: 74 | S59: 29 | T59: 75.3
A60: 40 | B60: 40 | I60: 40 | J60: 49.914025 | K60: 58.962751 | M60: 51.452852 | P60: 40 | Q60: 7.8 | R60: 65 | S60: 2 | T60: 96.58
A61: 49.714643 | B61: 52.443307 | I61: 46.82726 | J61: 46.626098 | K61: 66.397745 | M61: 46.807005 | P61: 44.219741 | Q61: 8.8 | R61: 51 | S61: 21 | T61: 95.82
A62: 53.273354 | B62: 50.911657 | I62: 49.40095 | J62: 56.463782 | K62: 64.558593 | P62: 64.169008 | Q62: 4.4 | R62: 94 | S62: 29 | T62: 67.49
A63: 55.013939 | B63: 68.578563 | I63: 59.615229 | J63: 61.131553 | K63: 40.504466 | P63: 59.554344 | Q63: 6.4 | R63: 83 | S63: 26 | T63: 70.26
A64: 41.381244 | B64: 53.476409 | I64: 46.551699 | K64: 50.487122 | P64: 53.494472 | Q64: 8.5 | R64: 95 | S64: 13 | T64: 89.43
A65: 43.109132 | B65: 49.398098 | I65: 58.341447 | K65: 60.160243 | P65: 55.379274 | Q65: 6.2 | R65: 75 | S65: 23 | T65: 65
A66: 48.176479 | B66: 60.068557 | I66: 46.470844 | K66: 48.236774 | P66: 46.423513 | Q66: 7.4 | R66: 60 | S66: 17 | T66: 93.76
A67: 55.69357 | B67: 58.578893 | I67: 52.635258 | K67: 40.048487 | P67: 46.360473 | Q67: 4.9 | R67: 73 | S67: 6 | T67: 77.47
A68: 40 | B68: 59.647937 | I68: 48.175694 | K68: 59.984999 | P68: 56.49708 | Q68: 5.2 | R68: 76 | S68: 29 | T68: 91.06
A69: 50.48711 | B69: 40 | I69: 42.806484 | K69: 60.072646 | P69: 40 | Q69: 6.1 | R69: 58 | S69: 13 | T69: 66.55
A70: 49.473501 | B70: 57.096524 | I70: 56.42082 | K70: 54.677353 | P70: 45.469367 | Q70: 5.6 | R70: 58 | S70: 19 | T70: 72.32
A71: 45.690764 | B71: 45.804314 | I71: 40 | K71: 58.146849 | P71: 49.252766 | Q71: 7.2 | R71: 93 | S71: 22 | T71: 67.48
A72: 50.378647 | B72: 53.656954 | I72: 51.403459 | K72: 50.104303 | P72: 52.608381 | Q72: 8.1 | R72: 75 | S72: 14 | T72: 71.29
A73: 50.263035 | B73: 54.370676 | I73: 58.659788 | K73: 61.66179 | P73: 48.779511 | Q73: 5.8 | R73: 84 | S73: 20 | T73: 78.45
A74: 41.38947 | B74: 55.58474 | I74: 56.956605 | P74: 46.640868 | Q74: 7.8 | R74: 48 | S74: 19 | T74: 82.2
A75: 46.658363 | B75: 64.250143 | I75: 57.422006 | P75: 44.767391 | Q75: 5.4 | R75: 56 | S75: 6 | T75: 97.06
A76: 41.323352 | B76: 50.751464 | I76: 57.351695 | P76: 56.531947 | Q76: 6 | R76: 88 | S76: 3 | T76: 86.95
A77: 54.836766 | B77: 40 | I77: 51.376386 | P77: 54.960969 | Q77: 4.2 | R77: 91 | S77: 14 | T77: 89.73
A78: 55.073614 | B78: 58.966551 | I78: 40.169604 | P78: 48.529102 | Q78: 4.7 | R78: 89 | S78: 28 | T78: 67.87
A79: 52.267974 | B79: 66.739606 | I79: 61.970291 | P79: 51.503041 | Q79: 4.6 | R79: 96 | S79: 10 | T79: 75.04
A80: 49.650183 | B80: 42.932271 | P80: 52.446168 | Q80: 6.9 | R80: 75 | S80: 3 | T80: 99.71
...

Sheet Correction analysis=
A1: Variable 1 | B1: Variable 2 | C1: Correction ®
A2: Final Exam Score | B2: Study Hours Per Week | C2: =CORREL(Table2[Final_Exam_Score],Table2[Study_Hours_Per_Week]) -> 0.31270244
A3: Final Exam Score | B3: Attendance Rate | C3: =CORREL(Table2[Final_Exam_Score],Table2[Attendance_Rate]) -> 0.27752604
A4: Final Exam Score | B4: Previous Grade | C4: =CORREL(Table2[Final_Exam_Score],Table2[Previous_Grade]) -> 0.74206067
A5: Final Exam Score | B5: Sleeping Hours | C5: =CORREL(Table2[Final_Exam_Score],Table2[Sleep_Hours_Per_Night]) -> -0.0069877298
A6: Study Hours per week | B6: Attendance Rate | C6: =CORREL(Table2[Study_Hours_Per_Week],Table2[Attendance_Rate]) -> 0.049050444 | E6: r= +1 Perfect positive
A7: Study Hours per week | B7: Sleeping Hours | C7: =CORREL(Table2[Study_Hours_Per_Week],Table2[Sleep_Hours_Per_Night]) -> -0.0066969349 | E7: r= -1 Perfect negative
E8: r= 0 no correlation
D10: 0.0- 0.3 | E10: weak
D11: 0.3-0.6 | E11: moderate
D12: 0.6-1.0 | E12: strong

Sheet Descriptive Summary
A1: Variable | B1: Count | C1: Mean | D1: Median | E1: Standard Deviation | F1: Min | G1: max
A2: Previous grade | B2: =COUNT(Table2[Previous_Grade]) -> 600 | C2: =AVERAGE(Student_Performance_Statistical!I581:I601) -> 73.142857 | D2: =MEDIAN(Student_Performance_Statistical!I586:I601) -> 68 | E2: =_xlfn.STDEV.S(Table2[Previous_Grade]) -> 15.979221 | F2: =MIN(Student_Performance_Statistical!I586:I601) -> 49 | G2: =MAX(Student_Performance_Statistical!I586:I601) -> 93
A3: Final Score | B3: =COUNT(Table2[Final_Exam_Score]) -> 600 | C3: =AVERAGE(Student_Performance_Statistical!K581:K601) -> 50.643204 | D3: =MEDIAN(Student_Performance_Statistical!K586:K601) -> 47.811871 | E3: =_xlfn.STDEV.S(Student_Performance_Statistical!K581:K601) -> 7.4136461 | F3: =MIN(Student_Performance_Statistical!K586:K601) -> 40 | G3: =MAX(Student_Performance_Statistical!K586:K601) -> 63.760029
A4: Attendance Rate | B4: =COUNT(Table2[Attendance_Rate]) -> 600 | C4: =AVERAGE(Student_Performance_Statistical!E581:E601) -> 83.594286 | D4: =MEDIAN(Student_Performance_Statistical!E586:E601) -> 86.145 | E4: =_xlfn.STDEV.S(Student_Performance_Statistical!E581:E601) -> 9.2697646 | F4: =MIN(Table2[Attendance_Rate]) -> 65 | G4: =MAX(Student_Performance_Statistical!E586:E601) -> 98.21
A5: Sleep hours | B5: =COUNT(Student_Performance_Statistical!J581:J601) -> 21 | C5: =AVERAGE(Student_Performance_Statistical!J586:J601) -> 6.48125 | D5: =MEDIAN(Student_Performance_Statistical!J586:J601) -> 6.85 | E5: =_xlfn.STDEV.S(Student_Performance_Statistical!J581:J601) -> 1.5046278 | F5: =MIN(Student_Performance_Statistical!J586:J601) -> 4.1 | G5: =MAX(Student_Performance_Statistical!J586:J601) -> 8.4
A6: Study hours | B6: =COUNT(Student_Performance_Statistical!D581:D601) -> 21 | C6: =AVERAGE(Student_Performance_Statistical!D586:D601) -> 12.4375 | D6: =AVERAGE(Student_Performance_Statistical!D586:D601) -> 12.4375 | E6: =_xlfn.STDEV.S(Student_Performance_Statistical!D581:D601) -> 7.2011904 | F6: =MIN(Student_Performance_Statistical!D586:D601) -> 2 | G6: =MAX(Student_Performance_Statistical!D586:D601) -> 21
